ERROR 2024-10-16 15:03:11,167 log Internal Server Error: /factoryoutlet/barcode/generate-barcode/
Traceback (most recent call last):
  File "/factoryoutlet/factoryoutlet/lib/python3.12/site-packages/django/core/handlers/exception.py", line 55, in inner
    response = get_response(request)
               ^^^^^^^^^^^^^^^^^^^^^
  File "/factoryoutlet/factoryoutlet/lib/python3.12/site-packages/django/core/handlers/base.py", line 197, in _get_response
    response = wrapped_callback(request, *callback_args, **callback_kwargs)
               ^^^^^^^^^^^^^^^^^^^^^^^^^^^^^^^^^^^^^^^^^^^^^^^^^^^^^^^^^^^^
  File "/factoryoutlet/factoryoutlet/lib/python3.12/site-packages/django/views/decorators/csrf.py", line 65, in _view_wrapper
    return view_func(request, *args, **kwargs)
           ^^^^^^^^^^^^^^^^^^^^^^^^^^^^^^^^^^^
  File "/factoryoutlet/factoryoutlet/lib/python3.12/site-packages/django/views/generic/base.py", line 104, in view
    return self.dispatch(request, *args, **kwargs)
           ^^^^^^^^^^^^^^^^^^^^^^^^^^^^^^^^^^^^^^^
  File "/factoryoutlet/factoryoutlet/lib/python3.12/site-packages/rest_framework/views.py", line 509, in dispatch
    response = self.handle_exception(exc)
               ^^^^^^^^^^^^^^^^^^^^^^^^^^
  File "/factoryoutlet/factoryoutlet/lib/python3.12/site-packages/rest_framework/views.py", line 469, in handle_exception
    self.raise_uncaught_exception(exc)
  File "/factoryoutlet/factoryoutlet/lib/python3.12/site-packages/rest_framework/views.py", line 480, in raise_uncaught_exception
    raise exc
  File "/factoryoutlet/factoryoutlet/lib/python3.12/site-packages/rest_framework/views.py", line 506, in dispatch
    response = handler(request, *args, **kwargs)
               ^^^^^^^^^^^^^^^^^^^^^^^^^^^^^^^^^
  File "/factoryoutlet/factoryoutlet/barcode/views.py", line 43, in post
    barcodes = self.new_barcode(prefix, number_of_barcodes, last_barcode)
               ^^^^^^^^^^^^^^^^^^^^^^^^^^^^^^^^^^^^^^^^^^^^^^^^^^^^^^^^^^
  File "/factoryoutlet/factoryoutlet/barcode/views.py", line 76, in new_barcode
    last_code += 1
    ^^^^^^^^^
UnboundLocalError: cannot access local variable 'last_code' where it is not associated with a value
ERROR 2024-10-16 15:03:11,171 basehttp "POST /factoryoutlet/barcode/generate-barcode/ HTTP/1.0" 500 99207
ERROR 2024-10-16 15:21:25,396 log Internal Server Error: /factoryoutlet/barcode/generate-barcode/
Traceback (most recent call last):
  File "/factoryoutlet/factoryoutlet/lib/python3.12/site-packages/django/core/handlers/exception.py", line 55, in inner
    response = get_response(request)
               ^^^^^^^^^^^^^^^^^^^^^
  File "/factoryoutlet/factoryoutlet/lib/python3.12/site-packages/django/core/handlers/base.py", line 197, in _get_response
    response = wrapped_callback(request, *callback_args, **callback_kwargs)
               ^^^^^^^^^^^^^^^^^^^^^^^^^^^^^^^^^^^^^^^^^^^^^^^^^^^^^^^^^^^^
  File "/factoryoutlet/factoryoutlet/lib/python3.12/site-packages/django/views/decorators/csrf.py", line 65, in _view_wrapper
    return view_func(request, *args, **kwargs)
           ^^^^^^^^^^^^^^^^^^^^^^^^^^^^^^^^^^^
  File "/factoryoutlet/factoryoutlet/lib/python3.12/site-packages/django/views/generic/base.py", line 104, in view
    return self.dispatch(request, *args, **kwargs)
           ^^^^^^^^^^^^^^^^^^^^^^^^^^^^^^^^^^^^^^^
  File "/factoryoutlet/factoryoutlet/lib/python3.12/site-packages/rest_framework/views.py", line 509, in dispatch
    response = self.handle_exception(exc)
               ^^^^^^^^^^^^^^^^^^^^^^^^^^
  File "/factoryoutlet/factoryoutlet/lib/python3.12/site-packages/rest_framework/views.py", line 469, in handle_exception
    self.raise_uncaught_exception(exc)
  File "/factoryoutlet/factoryoutlet/lib/python3.12/site-packages/rest_framework/views.py", line 480, in raise_uncaught_exception
    raise exc
  File "/factoryoutlet/factoryoutlet/lib/python3.12/site-packages/rest_framework/views.py", line 506, in dispatch
    response = handler(request, *args, **kwargs)
               ^^^^^^^^^^^^^^^^^^^^^^^^^^^^^^^^^
  File "/factoryoutlet/factoryoutlet/barcode/views.py", line 43, in post
    valid_type_instance.lat_pid = valid_type_instance.lat + number_of_barcodes
                                  ^^^^^^^^^^^^^^^^^^^^^^^
AttributeError: 'TypeT' object has no attribute 'lat'
ERROR 2024-10-16 15:21:25,402 basehttp "POST /factoryoutlet/barcode/generate-barcode/ HTTP/1.0" 500 94453
ERROR 2024-10-16 16:18:38,674 log Internal Server Error: /factoryoutlet/barcode/generate-barcode/
Traceback (most recent call last):
  File "/factoryoutlet/factoryoutlet/lib/python3.12/site-packages/django/db/backends/utils.py", line 105, in _execute
    return self.cursor.execute(sql, params)
           ^^^^^^^^^^^^^^^^^^^^^^^^^^^^^^^^
  File "/factoryoutlet/factoryoutlet/lib/python3.12/site-packages/django/db/backends/mysql/base.py", line 76, in execute
    return self.cursor.execute(query, args)
           ^^^^^^^^^^^^^^^^^^^^^^^^^^^^^^^^
  File "/factoryoutlet/factoryoutlet/lib/python3.12/site-packages/MySQLdb/cursors.py", line 179, in execute
    res = self._query(mogrified_query)
          ^^^^^^^^^^^^^^^^^^^^^^^^^^^^
  File "/factoryoutlet/factoryoutlet/lib/python3.12/site-packages/MySQLdb/cursors.py", line 330, in _query
    db.query(q)
  File "/factoryoutlet/factoryoutlet/lib/python3.12/site-packages/MySQLdb/connections.py", line 261, in query
    _mysql.connection.query(self, query)
MySQLdb.DataError: (1264, "Out of range value for column 'last_barcode' at row 1")

The above exception was the direct cause of the following exception:

Traceback (most recent call last):
  File "/factoryoutlet/factoryoutlet/lib/python3.12/site-packages/django/core/handlers/exception.py", line 55, in inner
    response = get_response(request)
               ^^^^^^^^^^^^^^^^^^^^^
  File "/factoryoutlet/factoryoutlet/lib/python3.12/site-packages/django/core/handlers/base.py", line 197, in _get_response
    response = wrapped_callback(request, *callback_args, **callback_kwargs)
               ^^^^^^^^^^^^^^^^^^^^^^^^^^^^^^^^^^^^^^^^^^^^^^^^^^^^^^^^^^^^
  File "/factoryoutlet/factoryoutlet/lib/python3.12/site-packages/django/views/decorators/csrf.py", line 65, in _view_wrapper
    return view_func(request, *args, **kwargs)
           ^^^^^^^^^^^^^^^^^^^^^^^^^^^^^^^^^^^
  File "/factoryoutlet/factoryoutlet/lib/python3.12/site-packages/django/views/generic/base.py", line 104, in view
    return self.dispatch(request, *args, **kwargs)
           ^^^^^^^^^^^^^^^^^^^^^^^^^^^^^^^^^^^^^^^
  File "/factoryoutlet/factoryoutlet/lib/python3.12/site-packages/rest_framework/views.py", line 509, in dispatch
    response = self.handle_exception(exc)
               ^^^^^^^^^^^^^^^^^^^^^^^^^^
  File "/factoryoutlet/factoryoutlet/lib/python3.12/site-packages/rest_framework/views.py", line 469, in handle_exception
    self.raise_uncaught_exception(exc)
  File "/factoryoutlet/factoryoutlet/lib/python3.12/site-packages/rest_framework/views.py", line 480, in raise_uncaught_exception
    raise exc
  File "/factoryoutlet/factoryoutlet/lib/python3.12/site-packages/rest_framework/views.py", line 506, in dispatch
    response = handler(request, *args, **kwargs)
               ^^^^^^^^^^^^^^^^^^^^^^^^^^^^^^^^^
  File "/factoryoutlet/factoryoutlet/barcode/views.py", line 43, in post
    valid_type_instance.save()
  File "/factoryoutlet/factoryoutlet/lib/python3.12/site-packages/django/db/models/base.py", line 891, in save
    self.save_base(
  File "/factoryoutlet/factoryoutlet/lib/python3.12/site-packages/django/db/models/base.py", line 997, in save_base
    updated = self._save_table(
              ^^^^^^^^^^^^^^^^^
  File "/factoryoutlet/factoryoutlet/lib/python3.12/site-packages/django/db/models/base.py", line 1129, in _save_table
    updated = self._do_update(
              ^^^^^^^^^^^^^^^^
  File "/factoryoutlet/factoryoutlet/lib/python3.12/site-packages/django/db/models/base.py", line 1194, in _do_update
    return filtered._update(values) > 0
           ^^^^^^^^^^^^^^^^^^^^^^^^
  File "/factoryoutlet/factoryoutlet/lib/python3.12/site-packages/django/db/models/query.py", line 1278, in _update
    return query.get_compiler(self.db).execute_sql(CURSOR)
           ^^^^^^^^^^^^^^^^^^^^^^^^^^^^^^^^^^^^^^^^^^^^^^^
  File "/factoryoutlet/factoryoutlet/lib/python3.12/site-packages/django/db/models/sql/compiler.py", line 2003, in execute_sql
    cursor = super().execute_sql(result_type)
             ^^^^^^^^^^^^^^^^^^^^^^^^^^^^^^^^
  File "/factoryoutlet/factoryoutlet/lib/python3.12/site-packages/django/db/models/sql/compiler.py", line 1574, in execute_sql
    cursor.execute(sql, params)
  File "/factoryoutlet/factoryoutlet/lib/python3.12/site-packages/django/db/backends/utils.py", line 122, in execute
    return super().execute(sql, params)
           ^^^^^^^^^^^^^^^^^^^^^^^^^^^^
  File "/factoryoutlet/factoryoutlet/lib/python3.12/site-packages/django/db/backends/utils.py", line 79, in execute
    return self._execute_with_wrappers(
           ^^^^^^^^^^^^^^^^^^^^^^^^^^^^
  File "/factoryoutlet/factoryoutlet/lib/python3.12/site-packages/django/db/backends/utils.py", line 92, in _execute_with_wrappers
    return executor(sql, params, many, context)
           ^^^^^^^^^^^^^^^^^^^^^^^^^^^^^^^^^^^^
  File "/factoryoutlet/factoryoutlet/lib/python3.12/site-packages/django/db/backends/utils.py", line 100, in _execute
    with self.db.wrap_database_errors:
  File "/factoryoutlet/factoryoutlet/lib/python3.12/site-packages/django/db/utils.py", line 91, in __exit__
    raise dj_exc_value.with_traceback(traceback) from exc_value
  File "/factoryoutlet/factoryoutlet/lib/python3.12/site-packages/django/db/backends/utils.py", line 105, in _execute
    return self.cursor.execute(sql, params)
           ^^^^^^^^^^^^^^^^^^^^^^^^^^^^^^^^
  File "/factoryoutlet/factoryoutlet/lib/python3.12/site-packages/django/db/backends/mysql/base.py", line 76, in execute
    return self.cursor.execute(query, args)
           ^^^^^^^^^^^^^^^^^^^^^^^^^^^^^^^^
  File "/factoryoutlet/factoryoutlet/lib/python3.12/site-packages/MySQLdb/cursors.py", line 179, in execute
    res = self._query(mogrified_query)
          ^^^^^^^^^^^^^^^^^^^^^^^^^^^^
  File "/factoryoutlet/factoryoutlet/lib/python3.12/site-packages/MySQLdb/cursors.py", line 330, in _query
    db.query(q)
  File "/factoryoutlet/factoryoutlet/lib/python3.12/site-packages/MySQLdb/connections.py", line 261, in query
    _mysql.connection.query(self, query)
django.db.utils.DataError: (1264, "Out of range value for column 'last_barcode' at row 1")
ERROR 2024-10-16 16:18:38,684 basehttp "POST /factoryoutlet/barcode/generate-barcode/ HTTP/1.0" 500 204985
